<?xml version="1.0"?>
<!--cp /media/chrx/TURBO/gym-robotable/gym_robotable/envs/robotable_with_gripper.urdf ./usr/local/lib/python3.6/dist-packages/gym/envs/gym_robotable/envs/
-->
<robot name="table">

  <material name="white">
    <color rgba="1 1 1 1"/>
  </material>

  <material name="black">
    <color rgba="0.2 0.2 0.2 1"/>
  </material>

  <material name="blue">
    <color rgba="0 0 1 1"/>
  </material>


	
  <link name="chassis">
    <visual>
      <geometry>
        <box size="2 2 0.1"/>
      </geometry>
      <origin rpy="0 0 0" xyz="0 0 1"/>
      <material name="white"/>
    </visual>
    <collision>
      <geometry>
        <box size="2 2 0.1"/>
      </geometry>
      <origin rpy="0 0 0" xyz="0 0 1"/>
      <contact_coefficients mu="0.08" />
    </collision>
    <inertial>
      <mass value="1"/>
      <inertia ixx="0.0" ixy="0.0" ixz="0.0" iyy="0.0" iyz="0.0" izz="0.0"/>
    </inertial>
  </link>
 


 
  <link name="r_upperleg">
    <visual>
      <geometry>
        <box size="0.1 0.1 1"/>
      </geometry>
      <origin rpy="0 0 0" xyz="0 0 -0.5"/>
      <material name="black"/>
    </visual>
    <collision>
      <geometry>
        <box size="0.1 0.1 1"/>
      </geometry>
      <origin rpy="0 0 0" xyz="0 0 -0.5"/>
      <contact_coefficients mu="0.08" />
    </collision>
    <inertial>
      <mass value="1"/>
      <inertia ixx="0.0" ixy="0.0" ixz="0.0" iyy="0.0" iyz="0.0" izz="0.0"/>
    </inertial>
  </link>


  <joint name="motor_front_right_leg_joint" type="revolute">
    <parent link="chassis"/>
    <child link="r_upperleg"/>
    <axis xyz="1 0 0"/>
    <limit effort="0.0" lower="-1.57." upper="1.57" velocity="1000.0"/>
    <origin rpy="0 0 0" xyz="1 1 1"/>
  </joint>






  <link name="l_upperleg">
    <visual>
      <geometry>
        <box size="0.1 0.1 1"/>
      </geometry>
      <origin rpy="0 0 0" xyz="0 0 -0.5"/>
      <material name="black"/>
    </visual>
    <collision>
      <geometry>
        <box size="0.1 0.1 1"/>
      </geometry>
      <origin rpy="0 0 0" xyz="0 0 -0.5"/>
      <contact_coefficients mu="0.08" />
    </collision>
    <inertial>
      <mass value="1"/>
      <inertia ixx="0.0" ixy="0.0" ixz="0.0" iyy="0.0" iyz="0.0" izz="0.0"/>
    </inertial>
  </link>


  <joint name="motor_front_left_leg_joint" type="revolute">
    <parent link="chassis"/>
    <child link="l_upperleg"/>
    <axis xyz="1 0 0"/>
    <limit effort="10.0" lower="-1.57." upper="1.57" velocity="1000.0"/>
    <origin rpy="0 0 0" xyz="-1 1 1"/>
  </joint>








  <link name="front_r_upperleg">
    <visual>
      <geometry>
        <box size="0.1 0.1 1"/>
      </geometry>
      <origin rpy="0 0 0" xyz="0 0 -0.5"/>
      <material name="black"/>
    </visual>
    <collision>
      <geometry>
        <box size="0.1 0.1 1"/>
      </geometry>
      <origin rpy="0 0 0" xyz="0 0 -0.5"/>
      <contact_coefficients mu="0.08" />
    </collision>
    <inertial>
      <mass value="1"/>
      <inertia ixx="0.0" ixy="0.0" ixz="0.0" iyy="0.0" iyz="0.0" izz="0.0"/>
    </inertial>
  </link>


  <joint name="motor_back_right_leg_joint" type="revolute">
    <parent link="chassis"/>
    <child link="front_r_upperleg"/>
    <axis xyz="1 0 0"/>
    <limit effort="0.0" lower="-1.57." upper="1.57" velocity="1000.0"/>
    <origin rpy="0 0 0" xyz="1 -1 1"/>
  </joint>








  <link name="front_l_upperleg">
    <visual>
      <geometry>
        <box size="0.1 0.1 1"/>
      </geometry>
      <origin rpy="0 0 0" xyz="0 0 -0.5"/>
      <material name="black"/>
    </visual>
    <collision>
      <geometry>
        <box size="0.1 0.1 1"/>
      </geometry>
      <origin rpy="0 0 0" xyz="0 0 -0.5"/>
      <contact_coefficients mu="0.08" />
    </collision>
   <inertial>
      <mass value="1"/>
      <inertia ixx="0.0" ixy="0.0" ixz="0.0" iyy="0.0" iyz="0.0" izz="0.0"/>
    </inertial>
  </link>


  <joint name="motor_back_left_leg_joint" type="revolute">
    <parent link="chassis"/>
    <child link="front_l_upperleg"/>
    <axis xyz="1 0 0"/>
    <limit effort="10.0" lower="-1.57." upper="1.57" velocity="1000.0"/>
    <origin rpy="0 0 0" xyz="-1 -1 1"/>
  </joint>




  <link name="neck_0">
    <visual>
      <geometry>
        <cylinder length="0.1" radius="0.1"/>
      </geometry>
      <origin rpy="0 0 0" xyz="0 0 0"/>
      <material name="blue"/>
    </visual>
    <collision>
      <geometry>
        <cylinder length="0.1" radius="0.1"/>
      </geometry>
      <origin rpy="0 0 0" xyz="0 0 0"/>
      <contact_coefficients mu="0.08" />
    </collision>
   <inertial>
      <mass value="1.618"/>
      <inertia ixx="0.0" ixy="0.0" ixz="0.0" iyy="0.0" iyz="0.0" izz="0.0"/>
    </inertial>
  </link>


  <joint name="gripper_joint_0" type="revolute">
    <parent link="chassis"/>
    <child link="neck_0"/>
    <axis xyz="0 0 1"/>
    <limit effort="10.0" lower="-1.57." upper="1.57" velocity="1000.0"/>
    <origin rpy="0 0 0" xyz="0 0.618 1.1"/>
  </joint>





  <link name="neck_1">
    <visual>
      <geometry>
        <box size="0.1 0.1 1.618"/>
      </geometry>
      <origin rpy="0 0 0" xyz="0 0 -0.9"/>
      <material name="black"/>
    </visual>
    <collision>
      <geometry>
        <box size="0.1 0.1 1.618"/>
      </geometry>
      <origin rpy="0 0 0" xyz="0 0 -0.9"/>
      <contact_coefficients mu="0.08" />
    </collision>
   <inertial>
      <mass value="1.618"/>
      <inertia ixx="0.0" ixy="0.0" ixz="0.0" iyy="0.0" iyz="0.0" izz="0.0"/>
    </inertial>
  </link>


  <joint name="gripper_joint_1" type="revolute">
    <parent link="neck_0"/>
    <child link="neck_1"/>
    <axis xyz="1 0 0"/>
    <limit effort="10.0" lower="-1.57." upper="1.57" velocity="1000.0"/>
    <origin rpy="2.7 0 0" xyz="0 0 0"/>
  </joint>






  <link name="neck_2">
    <visual>
      <geometry>
        <box size="0.1 0.1 1"/>
      </geometry>
      <origin rpy="0 0 0" xyz="0 0 -.618"/>
      <material name="blue"/>
    </visual>
    <collision>
      <geometry>
        <box size="0.1 0.1 1"/>
      </geometry>
      <origin rpy="0 0 0" xyz="0 0 -.618"/>
      <contact_coefficients mu="0.08" />
    </collision>
   <inertial>
      <mass value="1"/>
      <inertia ixx="0.0" ixy="0.0" ixz="0.0" iyy="0.0" iyz="0.0" izz="0.0"/>
    </inertial>
  </link>


  <joint name="gripper_joint_2" type="revolute">
    <parent link="neck_1"/>
    <child link="neck_2"/>
    <axis xyz="1 0 0"/>
    <limit effort="10.0" lower="-1.57." upper="1.57" velocity="1000.0"/>
    <origin rpy="-0.9 0 0" xyz="0 0 -1.718"/>
  </joint>






  <link name="neck_3">
    <visual>
      <geometry>
        <box size="0.1 0.1 0.618"/>
      </geometry>
      <origin rpy="0 0 0" xyz="0 0 -0.5"/>
      <material name="black"/>
    </visual>
    <collision>
      <geometry>
        <box size="0.1 0.1 0.618"/>
      </geometry>
      <origin rpy="0 0 0" xyz="0 0 -0.5"/>
      <contact_coefficients mu="0.08" />
    </collision>
   <inertial>
      <mass value="1"/>
      <inertia ixx="0.0" ixy="0.0" ixz="0.0" iyy="0.0" iyz="0.0" izz="0.0"/>
    </inertial>
  </link>


  <joint name="gripper_joint_3" type="revolute">
    <parent link="neck_2"/>
    <child link="neck_3"/>
    <axis xyz="1 0 0"/>
    <limit effort="10.0" lower="-1.57." upper="1.57" velocity="1000.0"/>
    <origin rpy="0 0 0" xyz="0 0 -1"/>
  </joint>



</robot>
